<?xml version="1.0" encoding="utf-8"?><testsuites><testsuite name="pytest" errors="1" failures="0" skipped="0" tests="1" time="9.048" timestamp="2025-08-02T13:58:10.360563-04:00" hostname="eleanor"><testcase classname="" name="tests.e2e.test_real_system_e2e" time="0.000"><error message="collection failure">+ Exception Group Traceback (most recent call last):
  |   File "/home/nick/anaconda3/lib/python3.11/site-packages/_pytest/runner.py", line 341, in from_call
  |     result: TResult | None = func()
  |                              ^^^^^^
  |   File "/home/nick/anaconda3/lib/python3.11/site-packages/_pytest/runner.py", line 389, in collect
  |     return list(collector.collect())
  |                 ^^^^^^^^^^^^^^^^^^^
  |   File "/home/nick/anaconda3/lib/python3.11/site-packages/pytest_asyncio/plugin.py", line 644, in _patched_collect
  |     module = collector.obj
  |              ^^^^^^^^^^^^^
  |   File "/home/nick/anaconda3/lib/python3.11/site-packages/_pytest/python.py", line 284, in obj
  |     self._obj = obj = self._getobj()
  |                       ^^^^^^^^^^^^^^
  |   File "/home/nick/anaconda3/lib/python3.11/site-packages/_pytest/python.py", line 546, in _getobj
  |     return importtestmodule(self.path, self.config)
  |            ^^^^^^^^^^^^^^^^^^^^^^^^^^^^^^^^^^^^^^^^
  |   File "/home/nick/anaconda3/lib/python3.11/site-packages/_pytest/python.py", line 493, in importtestmodule
  |     mod = import_path(
  |           ^^^^^^^^^^^^
  |   File "/home/nick/anaconda3/lib/python3.11/site-packages/_pytest/pathlib.py", line 582, in import_path
  |     importlib.import_module(module_name)
  |   File "/home/nick/anaconda3/lib/python3.11/importlib/__init__.py", line 126, in import_module
  |     return _bootstrap._gcd_import(name[level:], package, level)
  |            ^^^^^^^^^^^^^^^^^^^^^^^^^^^^^^^^^^^^^^^^^^^^^^^^^^^^
  |   File "&lt;frozen importlib._bootstrap&gt;", line 1204, in _gcd_import
  |   File "&lt;frozen importlib._bootstrap&gt;", line 1176, in _find_and_load
  |   File "&lt;frozen importlib._bootstrap&gt;", line 1147, in _find_and_load_unlocked
  |   File "&lt;frozen importlib._bootstrap&gt;", line 690, in _load_unlocked
  |   File "/home/nick/anaconda3/lib/python3.11/site-packages/_pytest/assertion/rewrite.py", line 174, in exec_module
  |     exec(co, module.__dict__)
  |   File "/home/nick/shannon-mcp/tests/e2e/test_real_system_e2e.py", line 25, in &lt;module&gt;
  |     from shannon_mcp.server_fastmcp import ServerState, main
  |   File "/home/nick/shannon-mcp/src/shannon_mcp/server_fastmcp.py", line 2888, in &lt;module&gt;
  |     @mcp_server.run()
  |      ^^^^^^^^^^^^^^^^
  |   File "/home/nick/anaconda3/lib/python3.11/site-packages/fastmcp/server/server.py", line 328, in run
  |     anyio.run(
  |   File "/home/nick/anaconda3/lib/python3.11/site-packages/anyio/_core/_eventloop.py", line 74, in run
  |     return async_backend.run(func, args, {}, backend_options)
  |            ^^^^^^^^^^^^^^^^^^^^^^^^^^^^^^^^^^^^^^^^^^^^^^^^^^
  |   File "/home/nick/anaconda3/lib/python3.11/site-packages/anyio/_backends/_asyncio.py", line 2310, in run
  |     return runner.run(wrapper())
  |            ^^^^^^^^^^^^^^^^^^^^^
  |   File "/home/nick/anaconda3/lib/python3.11/asyncio/runners.py", line 118, in run
  |     return self._loop.run_until_complete(task)
  |            ^^^^^^^^^^^^^^^^^^^^^^^^^^^^^^^^^^^
  |   File "/home/nick/anaconda3/lib/python3.11/asyncio/base_events.py", line 653, in run_until_complete
  |     return future.result()
  |            ^^^^^^^^^^^^^^^
  |   File "/home/nick/anaconda3/lib/python3.11/site-packages/anyio/_backends/_asyncio.py", line 2298, in wrapper
  |     return await func(*args)
  |            ^^^^^^^^^^^^^^^^^
  |   File "/home/nick/anaconda3/lib/python3.11/site-packages/fastmcp/server/server.py", line 303, in run_async
  |     await self.run_stdio_async(
  |   File "/home/nick/anaconda3/lib/python3.11/site-packages/fastmcp/server/server.py", line 1370, in run_stdio_async
  |     async with stdio_server() as (read_stream, write_stream):
  |   File "/home/nick/anaconda3/lib/python3.11/contextlib.py", line 211, in __aexit__
  |     await anext(self.gen)
  |   File "/home/nick/anaconda3/lib/python3.11/site-packages/mcp/server/stdio.py", line 85, in stdio_server
  |     async with anyio.create_task_group() as tg:
  |   File "/home/nick/anaconda3/lib/python3.11/site-packages/anyio/_backends/_asyncio.py", line 772, in __aexit__
  |     raise BaseExceptionGroup(
  | ExceptionGroup: unhandled errors in a TaskGroup (1 sub-exception)
  +-+---------------- 1 ----------------
    | Traceback (most recent call last):
    |   File "/home/nick/anaconda3/lib/python3.11/site-packages/mcp/server/stdio.py", line 63, in stdin_reader
    |     async for line in stdin:
    |   File "/home/nick/anaconda3/lib/python3.11/site-packages/anyio/_core/_fileio.py", line 83, in __aiter__
    |     line = await self.readline()
    |            ^^^^^^^^^^^^^^^^^^^^^
    |   File "/home/nick/anaconda3/lib/python3.11/site-packages/anyio/_core/_fileio.py", line 99, in readline
    |     return await to_thread.run_sync(self._fp.readline)
    |            ^^^^^^^^^^^^^^^^^^^^^^^^^^^^^^^^^^^^^^^^^^^
    |   File "/home/nick/anaconda3/lib/python3.11/site-packages/anyio/to_thread.py", line 56, in run_sync
    |     return await get_async_backend().run_sync_in_worker_thread(
    |            ^^^^^^^^^^^^^^^^^^^^^^^^^^^^^^^^^^^^^^^^^^^^^^^^^^^^
    |   File "/home/nick/anaconda3/lib/python3.11/site-packages/anyio/_backends/_asyncio.py", line 2470, in run_sync_in_worker_thread
    |     return await future
    |            ^^^^^^^^^^^^
    |   File "/home/nick/anaconda3/lib/python3.11/site-packages/anyio/_backends/_asyncio.py", line 967, in run
    |     result = context.run(func, *args)
    |              ^^^^^^^^^^^^^^^^^^^^^^^^
    | io.UnsupportedOperation: not readable
    +------------------------------------</error></testcase></testsuite></testsuites>